<?xml version="1.0"?>

<robot xmlns:xacro="http://www.ros.org/wiki/xacro">


    <xacro:property name="base_length" value="0.6" />
    <xacro:property name="base_width" value="0.4" />
    <xacro:property name="base_height" value="0.2" />
    <xacro:property name="wheel_radius" value="0.1" />
    <xacro:property name="wheel_length" value="0.05" />

    <link name="base_footprint" />

    <link name="base_link">
        <visual>
            <geometry>
                <box size="0.6 0.4 0.2"/>
            </geometry>
            <origin xyz="0 0 0.1" rpy="0 0 0"/>
            <material name="green" />
        </visual>
        <collision>
            <geometry>
                <box size="0.6 0.4 0.2"/>
            </geometry>
            <origin xyz="0 0 0.1" rpy="0 0 0"/>
        </collision>
        <xacro:box_inertia m="2" l="${2*base_length}" w="${2*base_width}" h="${2*base_height}" 
                           xyz="0 0 0.1" rpy="0 0 0" />
    </link>


    

    <xacro:macro name="wheel_link" params="prefix">
        <link name="${prefix} wheel">
            <visual>
                <geometry>
                    <cylinder radius="0.1" length="0.05"/>
                </geometry>
                <origin xyz="0 0 0" rpy="1.57 0 0"/>
                <material name="grey" />
            </visual>
            <collision>
                <geometry>
                    <cylinder radius="0.1" length="0.05"/>
                </geometry>
                <origin xyz="0 0 0" rpy="1.57 0 0"/>
            </collision>
            <xacro:cylinder_inertia m="0.2" r="${2*wheel_radius}" h="${2*wheel_length}"
                                    xyz="0 0 0" rpy="1.57 0 0" />
        </link>
    </xacro:macro>

    <xacro:wheel_link prefix="right_back" />
    <xacro:wheel_link prefix="right_front" />
    <xacro:wheel_link prefix="left_back" />
    <xacro:wheel_link prefix="left_front" />


    

    <joint name="base_right_back_wheel" type="continuous">
        <parent link="base_link" />
        <child link="right_back wheel" />
        <origin xyz="-0.15 -0.225 0" rpy="0 0 0"/>
        <axis xyz="0 1 0"/>
    </joint>

    <joint name="base_right_front_wheel" type="continuous">
        <parent link="base_link" />
        <child link="right_front wheel" />
        <origin xyz="0.15 -0.225 0" rpy="0 0 0"/>
        <axis xyz="0 1 0"/>
    </joint>

    <joint name="base_left_back_wheel" type="continuous">
        <parent link="base_link" />
        <child link="left_back wheel" />
        <origin xyz="-0.15 0.225 0" rpy="0 0 0"/>
        <axis xyz="0 1 0"/>
    </joint>

    <joint name="base_left_front_wheel" type="continuous">
        <parent link="base_link" />
        <child link="left_front wheel" />
        <origin xyz="0.15 0.225 0" rpy="0 0 0"/>
        <axis xyz="0 1 0"/>
    </joint>

    <joint name="base_link_footprint" type="fixed">
        <parent link="base_footprint" />
        <child link="base_link" />
        <origin xyz="0 0 0.1" rpy="0 0 0"/>

    </joint>    

    

</robot>